I"V<ul>
  <li><strong>Exception</strong>:
    <ul>
      <li>Similar problem: <a href="https://github.com/pypa/pip/issues/6251">link</a></li>
      <li>
        <p>The ValueError raised after typed<br />
  <code class="highlighter-rouge">pip3 freeze &gt; requirements.txt&gt;</code></p>

        <p>and it gave:
  <code class="highlighter-rouge">FileNotFoundError: [Errno 2] No such file or directory: '/home/user/anaconda3/lib/python3.6/site-packages/psutil-5.4.8.dist-info/METADATA'</code></p>

        <p>Output:</p>
        <pre class="brush: bash">
  Error checking for conflicts.
  Traceback (most recent call last):
  File "/home/jwfu/anaconda3/lib/python3.6/site-packages/pip/_vendor/pkg_resources/__init__.py", line 2897, in _dep_map
      return self.__dep_map
  File "/home/jwfu/anaconda3/lib/python3.6/site-packages/pip/_vendor/pkg_resources/__init__.py", line 2691, in __getattr__
      raise AttributeError(attr)
  AttributeError: _DistInfoDistribution__dep_map
  \n
  During handling of the above exception, another exception occurred:
  \n
  Traceback (most recent call last):
  File "/home/jwfu/anaconda3/lib/python3.6/site-packages/pip/_vendor/pkg_resources/__init__.py", line 2888, in _parsed_pkg_info
      return self._pkg_info
  File "/home/jwfu/anaconda3/lib/python3.6/site-packages/pip/_vendor/pkg_resources/__init__.py", line 2691, in __getattr__
      raise AttributeError(attr)
  AttributeError: _pkg_info
  \n
  During handling of the above exception, another exception occurred:

  Traceback (most recent call last):
      File "/home/jwfu/anaconda3/lib/python3.6/site-packages/pip/_internal/commands/install.py", line 503, in _warn_about_conflicts
          package_set, _dep_info = check_install_conflicts(to_install)
      File "/home/jwfu/anaconda3/lib/python3.6/site-packages/pip/_internal/operations/check.py", line 108, in check_install_conflicts
      	package_set, _ = create_package_set_from_installed()
  	File "/home/jwfu/anaconda3/lib/python3.6/site-packages/pip/_internal/operations/check.py", line 47, in create_package_set_from_installed
      	package_set[name] = PackageDetails(dist.version, dist.requires())
  	File "/home/jwfu/anaconda3/lib/python3.6/site-packages/pip/_vendor/pkg_resources/__init__.py", line 2635, in requires
      	dm = self._dep_map
  	File "/home/jwfu/anaconda3/lib/python3.6/site-packages/pip/_vendor/pkg_resources/__init__.py", line 2899, in _dep_map
      	self.__dep_map = self._compute_dependencies()
  	File "/home/jwfu/anaconda3/lib/python3.6/site-packages/pip/_vendor/pkg_resources/__init__.py", line 2908, in _compute_dependencies
      	for req in self._parsed_pkg_info.get_all('Requires-Dist') or []:
  	File "/home/jwfu/anaconda3/lib/python3.6/site-packages/pip/_vendor/pkg_resources/__init__.py", line 2890, in _parsed_pkg_info
      	metadata = self.get_metadata(self.PKG_INFO)
  	File "/home/jwfu/anaconda3/lib/python3.6/site-packages/pip/_vendor/pkg_resources/__init__.py", line 1410, in get_metadata
      	value = self._get(self._fn(self.egg_info, name))
  		File "/home/jwfu/anaconda3/lib/python3.6/site-packages/pip/_vendor/pkg_resources/__init__.py", line 1522, in _get
      	with open(path, 'rb') as stream:
  FileNotFoundError: [Errno 2] No such file or directory: '/home/jwfu/anaconda3/lib/python3.6/site-packages/psutil-5.4.8.dist-info/METADATA'</pre>
      </li>
      <li>Stackoverflow question <a href="https://stackoverflow.com/questions/54454367/different-error-messages-when-using-pip-install-pip-list-ect">link</a></li>
    </ul>
  </li>
  <li>
    <p><strong>root cause explanation</strong>: reffered to <a href="https://github.com/pypa/pip/pull/6225">here</a>.</p>
  </li>
  <li><strong>howto fix</strong>:
    <ol>
      <li>for each folder that starts with ‚Äú-‚Äú, delete it and reinstall the corresponding package.</li>
      <li>modify in <em>/src/pip/_internal/utils/temp_dir.py</em>
 <code class="highlighter-rouge">LEADING_CHARS = "-~.+=%0123456789"
 -&gt; LEADING_CHARS = "~.=%0123456789"</code></li>
    </ol>
  </li>
</ul>

<p>Error checking for conflicts.
Traceback (most recent call last):
  File ‚Äú/home/jwfu/anaconda3/lib/python3.6/site-packages/pip/_vendor/pkg_resources/<strong>init</strong>.py‚Äù, line 2897, in _dep_map
    return self.<strong>dep_map
  File ‚Äú/home/jwfu/anaconda3/lib/python3.6/site-packages/pip/_vendor/pkg_resources/__init</strong>.py‚Äù, line 2691, in <strong>getattr</strong>
    raise AttributeError(attr)
AttributeError: _DistInfoDistribution__dep_map</p>

<p>During handling of the above exception, another exception occurred:</p>

<p>Traceback (most recent call last):
  File ‚Äú/home/jwfu/anaconda3/lib/python3.6/site-packages/pip/_vendor/pkg_resources/<strong>init</strong>.py‚Äù, line 2888, in _parsed_pkg_info
    return self._pkg_info
  File ‚Äú/home/jwfu/anaconda3/lib/python3.6/site-packages/pip/_vendor/pkg_resources/<strong>init</strong>.py‚Äù, line 2691, in <strong>getattr</strong>
    raise AttributeError(attr)
AttributeError: _pkg_info</p>

<p>During handling of the above exception, another exception occurred:</p>

<p>Traceback (most recent call last):
  File ‚Äú/home/jwfu/anaconda3/lib/python3.6/site-packages/pip/_internal/commands/install.py‚Äù, line 503, in _warn_about_conflicts
    package_set, _dep_info = check_install_conflicts(to_install)
  File ‚Äú/home/jwfu/anaconda3/lib/python3.6/site-packages/pip/_internal/operations/check.py‚Äù, line 108, in check_install_conflicts
    package_set, _ = create_package_set_from_installed()
  File ‚Äú/home/jwfu/anaconda3/lib/python3.6/site-packages/pip/_internal/operations/check.py‚Äù, line 47, in create_package_set_from_installed
    package_set[name] = PackageDetails(dist.version, dist.requires())
  File ‚Äú/home/jwfu/anaconda3/lib/python3.6/site-packages/pip/_vendor/pkg_resources/<strong>init</strong>.py‚Äù, line 2635, in requires
    dm = self._dep_map
  File ‚Äú/home/jwfu/anaconda3/lib/python3.6/site-packages/pip/_vendor/pkg_resources/<strong>init</strong>.py‚Äù, line 2899, in _dep_map
    self.<strong>dep_map = self._compute_dependencies()
  File ‚Äú/home/jwfu/anaconda3/lib/python3.6/site-packages/pip/_vendor/pkg_resources/__init</strong>.py‚Äù, line 2908, in _compute_dependencies
    for req in self._parsed_pkg_info.get_all(‚ÄòRequires-Dist‚Äô) or []:
  File ‚Äú/home/jwfu/anaconda3/lib/python3.6/site-packages/pip/_vendor/pkg_resources/<strong>init</strong>.py‚Äù, line 2890, in _parsed_pkg_info
    metadata = self.get_metadata(self.PKG_INFO)
  File ‚Äú/home/jwfu/anaconda3/lib/python3.6/site-packages/pip/_vendor/pkg_resources/<strong>init</strong>.py‚Äù, line 1410, in get_metadata
    value = self._get(self._fn(self.egg_info, name))
  File ‚Äú/home/jwfu/anaconda3/lib/python3.6/site-packages/pip/_vendor/pkg_resources/<strong>init</strong>.py‚Äù, line 1522, in _get
    with open(path, ‚Äòrb‚Äô) as stream:
FileNotFoundError: [Errno 2] No such file or directory: ‚Äò/home/jwfu/anaconda3/lib/python3.6/site-packages/psutil-5.4.8.dist-info/METADATA‚Äô</p>
:ET